  fixed exception in django test runner with custom test_runner function  